<sdf version="1.6">
  <model name="iai_donbot">
    <link name="base_footprint">
      <pose frame="">0 0 0 0 -0 0</pose>
      <inertial>
        <pose frame="">-0.016311 -0.013447 0.237645 0 -0 0</pose>
        <mass>74.0212</mass>
        <inertia>
          <ixx>9.86762</ixx>
          <ixy>-0.105452</ixy>
          <ixz>1.08785</ixz>
          <iyy>13.4675</iyy>
          <iyz>0.311726</iyz>
          <izz>7.87289</izz>
        </inertia>
      </inertial>
      <collision name="base_footprint_collision">
        <pose frame="">0 0 0 0 -0 0</pose>
        <geometry>
          <box>
            <size>0.01 0.01 0.01</size>
          </box>
        </geometry>
      </collision>
      <collision name="base_footprint_fixed_joint_lump__base_link_collision_1">
        <pose frame="">0.25525 0.225 0.1616 0 -0 0</pose>
        <geometry>
          <mesh>
            <scale>1 1 1</scale>
            <uri>model://iai_donbot_description/meshes/iai_boxy_base_2/base_lowres.fbx</uri>
          </mesh>
        </geometry>
      </collision>
      <collision name="base_footprint_fixed_joint_lump__ur5_base_link_collision_2">
        <pose frame="">-0.26975 -0.199 0.6316 0 -0 0</pose>
        <geometry>
          <mesh>
            <scale>1 1 1</scale>
            <uri>model://iai_donbot_description/meshes/ur5/collision/base.fbx</uri>
          </mesh>
        </geometry>
      </collision>
      <collision name="base_footprint_fixed_joint_lump__charger_collision_3">
        <pose frame="">0.33025 0 0.3516 0 -0 0</pose>
        <geometry>
          <box>
            <size>0.15 0.3 0.38</size>
          </box>
        </geometry>
      </collision>
      <collision name="base_footprint_fixed_joint_lump__e_stop_collision_4">
        <pose frame="">0.22025 0.2235 0.6816 0 -0 0</pose>
        <geometry>
          <box>
            <size>0.07 0.07 0.1</size>
          </box>
        </geometry>
      </collision>
      <collision name="base_footprint_fixed_joint_lump__plate_collision_5">
        <pose frame="">-0.04475 -0.005 0.6216 0 -0 0</pose>
        <geometry>
          <box>
            <size>0.6 0.553 0.02</size>
          </box>
        </geometry>
      </collision>
      <collision name="base_footprint_fixed_joint_lump__switches_collision_6">
        <pose frame="">-0.40475 0 0.3866 0 -0 0</pose>
        <geometry>
          <box>
            <size>0.12 0.4 0.45</size>
          </box>
        </geometry>
      </collision>
      <collision name="base_footprint_fixed_joint_lump__ur5_touchpad_collision_7">
        <pose frame="">0.09525 -0.3105 0.5416 0 -0 0</pose>
        <geometry>
          <box>
            <size>0.32 0.06 0.24</size>
          </box>
        </geometry>
      </collision>
      <collision name="base_footprint_fixed_joint_lump__wlan_collision_8">
        <pose frame="">0.30525 0 0.5666 0 -0.314 0</pose>
        <geometry>
          <box>
            <size>0.25 0.14 0.05</size>
          </box>
        </geometry>
      </collision>
      <visual name="base_footprint_visual">
        <pose frame="">0 0 0 0 -0 0</pose>
        <geometry>
          <box>
            <size>0.01 0.01 0.01</size>
          </box>
        </geometry>
      </visual>
      <visual name="base_footprint_fixed_joint_lump__base_link_visual_1">
        <pose frame="">0.25525 0.225 0.1616 0 -0 0</pose>
        <geometry>
          <mesh>
            <scale>1 1 1</scale>
            <uri>model://iai_donbot_description/meshes/iai_boxy_base_2/boxy_base.fbx</uri>
          </mesh>
        </geometry>
      </visual>
      <visual name="base_footprint_fixed_joint_lump__ur5_base_link_visual_2">
        <pose frame="">-0.26975 -0.199 0.6316 0 -0 0</pose>
        <geometry>
          <mesh>
            <scale>1 1 1</scale>
            <uri>model://iai_donbot_description/meshes/ur5/visual/base.fbx</uri>
          </mesh>
        </geometry>
      </visual>
      <visual name="base_footprint_fixed_joint_lump__charger_visual_3">
        <pose frame="">0.33025 0 0.3516 0 -0 0</pose>
        <geometry>
          <box>
            <size>0.15 0.3 0.38</size>
          </box>
        </geometry>
      </visual>
      <visual name="base_footprint_fixed_joint_lump__e_stop_visual_4">
        <pose frame="">0.22025 0.2235 0.6816 0 -0 0</pose>
        <geometry>
          <box>
            <size>0.07 0.07 0.1</size>
          </box>
        </geometry>
      </visual>
      <visual name="base_footprint_fixed_joint_lump__plate_visual_5">
        <pose frame="">-0.04475 -0.005 0.6216 0 -0 0</pose>
        <geometry>
          <box>
            <size>0.6 0.553 0.02</size>
          </box>
        </geometry>
      </visual>
      <visual name="base_footprint_fixed_joint_lump__switches_visual_6">
        <pose frame="">-0.40475 0 0.3866 0 -0 0</pose>
        <geometry>
          <box>
            <size>0.12 0.4 0.45</size>
          </box>
        </geometry>
      </visual>
      <visual name="base_footprint_fixed_joint_lump__ur5_touchpad_visual_7">
        <pose frame="">0.09525 -0.3105 0.5416 0 -0 0</pose>
        <geometry>
          <box>
            <size>0.32 0.06 0.24</size>
          </box>
        </geometry>
      </visual>
      <visual name="base_footprint_fixed_joint_lump__wlan_visual_8">
        <pose frame="">0.30525 0 0.5666 0 -0.314 0</pose>
        <geometry>
          <box>
            <size>0.25 0.14 0.05</size>
          </box>
        </geometry>
      </visual>
    </link>
    <link name="ur5_shoulder_link">
      <pose frame="">-0.26975 -0.199 0.720759 0 -0 0</pose>
      <inertial>
        <pose frame="">0 0 0 0 -0 0</pose>
        <mass>3.7</mass>
        <inertia>
          <ixx>0.0102675</ixx>
          <ixy>0</ixy>
          <ixz>0</ixz>
          <iyy>0.0102675</iyy>
          <iyz>0</iyz>
          <izz>0.00666</izz>
        </inertia>
      </inertial>
      <collision name="ur5_shoulder_link_collision">
        <pose frame="">0 0 0 0 -0 0</pose>
        <geometry>
          <mesh>
            <scale>1 1 1</scale>
            <uri>model://iai_donbot_description/meshes/ur5/collision/shoulder.fbx</uri>
          </mesh>
        </geometry>
      </collision>
      <visual name="ur5_shoulder_link_visual">
        <pose frame="">0 0 0 0 -0 0</pose>
        <geometry>
          <mesh>
            <scale>1 1 1</scale>
            <uri>model://iai_donbot_description/meshes/ur5/visual/shoulder.fbx</uri>
          </mesh>
        </geometry>
      </visual>
    </link>
    <joint name="ur5_shoulder_pan_joint" type="revolute">
      <child>ur5_shoulder_link</child>
      <parent>base_footprint</parent>
      <axis>
        <xyz>0 0 1</xyz>
        <limit>
          <lower>-6.28319</lower>
          <upper>6.28319</upper>
          <effort>150</effort>
          <velocity>3.15</velocity>
        </limit>
        <dynamics>
          <damping>0</damping>
          <friction>0</friction>
          <spring_reference>0</spring_reference>
          <spring_stiffness>0</spring_stiffness>
        </dynamics>
        <use_parent_model_frame>1</use_parent_model_frame>
      </axis>
    </joint>
    <link name="ur5_upper_arm_link">
      <pose frame="">-0.26975 -0.06315 0.720759 3.14159 1.57079 3.14159</pose>
      <inertial>
        <pose frame="">0 0 0.28 0 -0 0</pose>
        <mass>8.393</mass>
        <inertia>
          <ixx>0.226891</ixx>
          <ixy>0</ixy>
          <ixz>0</ixz>
          <iyy>0.226891</iyy>
          <iyz>0</iyz>
          <izz>0.0151074</izz>
        </inertia>
      </inertial>
      <collision name="ur5_upper_arm_link_collision">
        <pose frame="">0 0 0 0 -0 0</pose>
        <geometry>
          <mesh>
            <scale>1 1 1</scale>
            <uri>model://iai_donbot_description/meshes/ur5/collision/upperarm.fbx</uri>
          </mesh>
        </geometry>
      </collision>
      <visual name="ur5_upper_arm_link_visual">
        <pose frame="">0 0 0 0 -0 0</pose>
        <geometry>
          <mesh>
            <scale>1 1 1</scale>
            <uri>model://iai_donbot_description/meshes/ur5/visual/upperarm.fbx</uri>
          </mesh>
        </geometry>
      </visual>
    </link>
    <joint name="ur5_shoulder_lift_joint" type="revolute">
      <child>ur5_upper_arm_link</child>
      <parent>ur5_shoulder_link</parent>
      <axis>
        <xyz>0 1 0</xyz>
        <limit>
          <lower>-6.28319</lower>
          <upper>6.28319</upper>
          <effort>150</effort>
          <velocity>3.15</velocity>
        </limit>
        <dynamics>
          <damping>0</damping>
          <friction>0</friction>
          <spring_reference>0</spring_reference>
          <spring_stiffness>0</spring_stiffness>
        </dynamics>
        <use_parent_model_frame>1</use_parent_model_frame>
      </axis>
    </joint>
    <link name="ur5_forearm_link">
      <pose frame="">0.15525 -0.18285 0.720759 3.14159 1.57079 3.14159</pose>
      <inertial>
        <pose frame="">0 0 0.25 0 -0 0</pose>
        <mass>2.275</mass>
        <inertia>
          <ixx>0.0494433</ixx>
          <ixy>0</ixy>
          <ixz>0</ixz>
          <iyy>0.0494433</iyy>
          <iyz>0</iyz>
          <izz>0.004095</izz>
        </inertia>
      </inertial>
      <collision name="ur5_forearm_link_collision">
        <pose frame="">0 0 0 0 -0 0</pose>
        <geometry>
          <mesh>
            <scale>1 1 1</scale>
            <uri>model://iai_donbot_description/meshes/ur5/collision/forearm.fbx</uri>
          </mesh>
        </geometry>
      </collision>
      <visual name="ur5_forearm_link_visual">
        <pose frame="">0 0 0 0 -0 0</pose>
        <geometry>
          <mesh>
            <scale>1 1 1</scale>
            <uri>model://iai_donbot_description/meshes/ur5/visual/forearm.fbx</uri>
          </mesh>
        </geometry>
      </visual>
    </link>
    <joint name="ur5_elbow_joint" type="revolute">
      <child>ur5_forearm_link</child>
      <parent>ur5_upper_arm_link</parent>
      <axis>
        <xyz>0 1 0</xyz>
        <limit>
          <lower>-6.28319</lower>
          <upper>6.28319</upper>
          <effort>150</effort>
          <velocity>3.15</velocity>
        </limit>
        <dynamics>
          <damping>0</damping>
          <friction>0</friction>
          <spring_reference>0</spring_reference>
          <spring_stiffness>0</spring_stiffness>
        </dynamics>
        <use_parent_model_frame>1</use_parent_model_frame>
      </axis>
    </joint>
    <link name="ur5_wrist_1_link">
      <pose frame="">0.5475 -0.18285 0.720759 3.14159 0 3.14159</pose>
      <inertial>
        <pose frame="">0 0 0 0 -0 0</pose>
        <mass>1.219</mass>
        <inertia>
          <ixx>0.111173</ixx>
          <ixy>0</ixy>
          <ixz>0</ixz>
          <iyy>0.111173</iyy>
          <iyz>0</iyz>
          <izz>0.21942</izz>
        </inertia>
      </inertial>
      <collision name="ur5_wrist_1_link_collision">
        <pose frame="">0 0 0 0 -0 0</pose>
        <geometry>
          <mesh>
            <scale>1 1 1</scale>
            <uri>model://iai_donbot_description/meshes/ur5/collision/wrist1.fbx</uri>
          </mesh>
        </geometry>
      </collision>
      <visual name="ur5_wrist_1_link_visual">
        <pose frame="">0 0 0 0 -0 0</pose>
        <geometry>
          <mesh>
            <scale>1 1 1</scale>
            <uri>model://iai_donbot_description/meshes/ur5/visual/wrist1.fbx</uri>
          </mesh>
        </geometry>
      </visual>
    </link>
    <joint name="ur5_wrist_1_joint" type="revolute">
      <child>ur5_wrist_1_link</child>
      <parent>ur5_forearm_link</parent>
      <axis>
        <xyz>0 1 0</xyz>
        <limit>
          <lower>-6.28319</lower>
          <upper>6.28319</upper>
          <effort>28</effort>
          <velocity>3.2</velocity>
        </limit>
        <dynamics>
          <damping>0</damping>
          <friction>0</friction>
          <spring_reference>0</spring_reference>
          <spring_stiffness>0</spring_stiffness>
        </dynamics>
        <use_parent_model_frame>1</use_parent_model_frame>
      </axis>
    </joint>
    <link name="ur5_wrist_2_link">
      <pose frame="">0.5475 -0.08985 0.720759 3.14159 0 3.14159</pose>
      <inertial>
        <pose frame="">0 0 0 0 -0 0</pose>
        <mass>1.219</mass>
        <inertia>
          <ixx>0.111173</ixx>
          <ixy>0</ixy>
          <ixz>0</ixz>
          <iyy>0.111173</iyy>
          <iyz>0</iyz>
          <izz>0.21942</izz>
        </inertia>
      </inertial>
      <collision name="ur5_wrist_2_link_collision">
        <pose frame="">0 0 0 0 -0 0</pose>
        <geometry>
          <mesh>
            <scale>1 1 1</scale>
            <uri>model://iai_donbot_description/meshes/ur5/collision/wrist2.fbx</uri>
          </mesh>
        </geometry>
      </collision>
      <visual name="ur5_wrist_2_link_visual">
        <pose frame="">0 0 0 0 -0 0</pose>
        <geometry>
          <mesh>
            <scale>1 1 1</scale>
            <uri>model://iai_donbot_description/meshes/ur5/visual/wrist2.fbx</uri>
          </mesh>
        </geometry>
      </visual>
    </link>
    <joint name="ur5_wrist_2_joint" type="revolute">
      <child>ur5_wrist_2_link</child>
      <parent>ur5_wrist_1_link</parent>
      <axis>
        <xyz>0 0 -1</xyz>
        <limit>
          <lower>-6.28319</lower>
          <upper>6.28319</upper>
          <effort>28</effort>
          <velocity>3.2</velocity>
        </limit>
        <dynamics>
          <damping>0</damping>
          <friction>0</friction>
          <spring_reference>0</spring_reference>
          <spring_stiffness>0</spring_stiffness>
        </dynamics>
        <use_parent_model_frame>1</use_parent_model_frame>
      </axis>
    </joint>
    <link name="ur5_wrist_3_link">
      <pose frame="">0.5475 -0.08985 0.626109 3.14159 0 3.14159</pose>
      <inertial>
        <pose frame="">0 0.091003 0 0 -0 0</pose>
        <mass>0.4379</mass>
        <inertia>
          <ixx>1.01986</ixx>
          <ixy>-6.45547e-15</ixy>
          <ixz>-1.91194e-31</ixz>
          <iyy>1.01714</iyy>
          <iyz>-8.07264e-20</iyz>
          <izz>1.03655</izz>
        </inertia>
      </inertial>
      <collision name="ur5_wrist_3_link_collision">
        <pose frame="">0 0 0 0 -0 0</pose>
        <geometry>
          <mesh>
            <scale>1 1 1</scale>
            <uri>model://iai_donbot_description/meshes/ur5/collision/wrist3.fbx</uri>
          </mesh>
        </geometry>
      </collision>
      <collision name="ur5_wrist_3_link_fixed_joint_lump__ur5_ee_link_collision_1">
        <pose frame="">-0 0.0723 0 0 -0 1.5708</pose>
        <geometry>
          <box>
            <size>0.01 0.01 0.01</size>
          </box>
        </geometry>
      </collision>
      <collision name="ur5_wrist_3_link_fixed_joint_lump__gripper_base_link_collision_2">
        <pose frame="">0 0.1594 0 -3.14159 1.57079 -1.5708</pose>
        <geometry>
          <mesh>
            <scale>1 1 1</scale>
            <uri>model://iai_donbot_description/meshes/iai_wsg_50/WSG50_110.fbx</uri>
          </mesh>
        </geometry>
      </collision>
      <collision name="ur5_wrist_3_link_fixed_joint_lump__camera_holder_link_collision_3">
        <pose frame="">0 0.1594 0 3.14159 -1.57079 1.57079</pose>
        <geometry>
          <mesh>
            <scale>1 1 1</scale>
            <uri>model://iai_donbot_description/meshes/iai_refills_camera/refills_camera_holder_and_camera.fbx</uri>
          </mesh>
        </geometry>
      </collision>
      <collision name="ur5_wrist_3_link_fixed_joint_lump__wrist_collision_collision_4">
        <pose frame="">0 0.1203 0 -3.14159 -1.57079 1.5708</pose>
        <geometry>
          <cylinder>
            <length>0.08</length>
            <radius>0.04</radius>
          </cylinder>
        </geometry>
      </collision>
      <visual name="ur5_wrist_3_link_visual">
        <pose frame="">0 0 0 0 -0 0</pose>
        <geometry>
          <mesh>
            <scale>1 1 1</scale>
            <uri>model://iai_donbot_description/meshes/ur5/visual/wrist3.fbx</uri>
          </mesh>
        </geometry>
      </visual>
      <visual name="ur5_wrist_3_link_fixed_joint_lump__kms_mounting_plate_visual_1">
        <pose frame="">0 0.0823 0 3.14159 1.57079 -1.57079</pose>
        <geometry>
          <mesh>
            <scale>0.001 0.001 0.001</scale>
            <uri>model://iai_donbot_description/meshes/iai_table_robot/adapter_plate_iso50_kms40_weiss.fbx</uri>
          </mesh>
        </geometry>
      </visual>
      <visual name="ur5_wrist_3_link_fixed_joint_lump__adapter_iso50_kms40_frame_in_visual_2">
        <pose frame="">0 0.0823 0 -3.14159 -1.57079 1.5708</pose>
        <geometry>
          <mesh>
            <scale>0.001 0.001 0.001</scale>
            <uri>model://iai_donbot_description/meshes/iai_kms_40/adapter_plate_iso50_kms40_weiss.fbx</uri>
          </mesh>
        </geometry>
      </visual>
      <visual name="ur5_wrist_3_link_fixed_joint_lump__kms40_frame_in_visual_3">
        <pose frame="">0 0.0983 0 -3.14159 -1.57079 1.5708</pose>
        <geometry>
          <mesh>
            <scale>0.001 0.001 0.001</scale>
            <uri>model://iai_donbot_description/meshes/iai_kms_40/kms40_simple.fbx</uri>
          </mesh>
        </geometry>
      </visual>
      <visual name="ur5_wrist_3_link_fixed_joint_lump__adapter_kms40_fwk050_frame_in_visual_4">
        <pose frame="">0 0.1253 0 -3.14159 -1.57079 1.5708</pose>
        <geometry>
          <mesh>
            <scale>0.001 0.001 0.001</scale>
            <uri>model://iai_donbot_description/meshes/iai_adapters/adapter_kms40_fwk050.fbx</uri>
          </mesh>
        </geometry>
      </visual>
      <visual name="ur5_wrist_3_link_fixed_joint_lump__fwk_fwa_050_frame_in_visual_5">
        <pose frame="">0 0.1353 0 -3.14159 -1.57079 1.5708</pose>
        <geometry>
          <mesh>
            <scale>0.001 0.001 0.001</scale>
            <uri>model://iai_donbot_description/meshes/iai_adapters/fwk_fwa_050_simple.fbx</uri>
          </mesh>
        </geometry>
      </visual>
      <visual name="ur5_wrist_3_link_fixed_joint_lump__adapter_fwa050_wsg50_frame_in_visual_6">
        <pose frame="">0 0.1494 0 -3.14159 -1.57079 1.5708</pose>
        <geometry>
          <mesh>
            <scale>0.001 0.001 0.001</scale>
            <uri>model://iai_donbot_description/meshes/iai_adapters/adapter_fwa050_wsg50.fbx</uri>
          </mesh>
        </geometry>
      </visual>
      <visual name="ur5_wrist_3_link_fixed_joint_lump__gripper_base_link_visual_7">
        <pose frame="">0 0.1594 0 -3.14159 1.57079 -1.5708</pose>
        <geometry>
          <mesh>
            <scale>1 1 1</scale>
            <uri>model://iai_donbot_description/meshes/iai_wsg_50/WSG50_110.fbx</uri>
          </mesh>
        </geometry>
      </visual>
      <visual name="ur5_wrist_3_link_fixed_joint_lump__camera_holder_link_visual_8">
        <pose frame="">0 0.1594 0 3.14159 -1.57079 1.57079</pose>
        <geometry>
          <mesh>
            <scale>1 1 1</scale>
            <uri>model://iai_donbot_description/meshes/iai_refills_camera/refills_camera_holder_and_camera.fbx</uri>
          </mesh>
        </geometry>
      </visual>
      <visual name="ur5_wrist_3_link_fixed_joint_lump__camera_link_visual_9">
        <pose frame="">0.066498 0.220347 -0.002956 1.90031 -1.55629 3.01649</pose>
        <geometry>
          <cylinder>
            <length>0.005</length>
            <radius>0.001</radius>
          </cylinder>
        </geometry>
      </visual>
    </link>
    <joint name="ur5_wrist_3_joint" type="revolute">
      <child>ur5_wrist_3_link</child>
      <parent>ur5_wrist_2_link</parent>
      <axis>
        <xyz>0 1 0</xyz>
        <limit>
          <lower>-6.28319</lower>
          <upper>6.28319</upper>
          <effort>28</effort>
          <velocity>3.2</velocity>
        </limit>
        <dynamics>
          <damping>0</damping>
          <friction>0</friction>
          <spring_reference>0</spring_reference>
          <spring_stiffness>0</spring_stiffness>
        </dynamics>
        <use_parent_model_frame>1</use_parent_model_frame>
      </axis>
    </joint>
    <link name="gripper_gripper_left_link">
      <pose frame="">0.5475 0.06955 0.622109 1.57079 -1.57079 3.14159</pose>
      <inertial>
        <pose frame="">0 0 0.0115 0 -0 0</pose>
        <mass>0.002</mass>
        <inertia>
          <ixx>2</ixx>
          <ixy>0</ixy>
          <ixz>0</ixz>
          <iyy>2</iyy>
          <iyz>0</iyz>
          <izz>2</izz>
        </inertia>
      </inertial>
      <collision name="gripper_gripper_left_link_collision">
        <pose frame="">0 0 0 0 -0 0</pose>
        <geometry>
          <mesh>
            <scale>0.001 0.001 0.001</scale>
            <uri>model://iai_donbot_description/meshes/iai_wsg_50/GUIDE_WSG50_110.fbx</uri>
          </mesh>
        </geometry>
      </collision>
      <collision name="gripper_gripper_left_link_fixed_joint_lump__gripper_finger_left_link_collision_1">
        <pose frame="">0 0 0.023 0 -0 0</pose>
        <geometry>
          <mesh>
            <scale>0.001 0.001 0.001</scale>
            <uri>model://iai_donbot_description/meshes/iai_wsg_50/WSG-FMF.fbx</uri>
          </mesh>
        </geometry>
      </collision>
      <visual name="gripper_gripper_left_link_visual">
        <pose frame="">0 0 0 0 -0 0</pose>
        <geometry>
          <mesh>
            <scale>0.001 0.001 0.001</scale>
            <uri>model://iai_donbot_description/meshes/iai_wsg_50/GUIDE_WSG50_110.fbx</uri>
          </mesh>
        </geometry>
      </visual>
      <visual name="gripper_gripper_left_link_fixed_joint_lump__gripper_finger_left_link_visual_1">
        <pose frame="">0 0 0.023 0 -0 0</pose>
        <geometry>
          <mesh>
            <scale>0.001 0.001 0.001</scale>
            <uri>model://iai_donbot_description/meshes/iai_wsg_50/WSG-FMF.fbx</uri>
          </mesh>
        </geometry>
      </visual>
    </link>
    <joint name="gripper_base_gripper_left_joint" type="prismatic">
      <child>gripper_gripper_left_link</child>
      <parent>ur5_wrist_3_link</parent>
      <axis>
        <xyz>-0 0 1</xyz>
        <limit>
          <lower>-0.051</lower>
          <upper>0</upper>
          <effort>10</effort>
          <velocity>0.42</velocity>
        </limit>
        <dynamics>
          <damping>1</damping>
          <friction>1</friction>
          <spring_reference>0</spring_reference>
          <spring_stiffness>0</spring_stiffness>
        </dynamics>
        <use_parent_model_frame>1</use_parent_model_frame>
      </axis>
    </joint>
    <link name="gripper_gripper_right_link">
      <pose frame="">0.5475 0.06955 0.630109 1.57079 1.57079 3.14159</pose>
      <inertial>
        <pose frame="">0 0 0.0115 0 -0 0</pose>
        <mass>0.002</mass>
        <inertia>
          <ixx>2</ixx>
          <ixy>0</ixy>
          <ixz>0</ixz>
          <iyy>2</iyy>
          <iyz>0</iyz>
          <izz>2</izz>
        </inertia>
      </inertial>
      <collision name="gripper_gripper_right_link_collision">
        <pose frame="">0 0 0 0 -0 0</pose>
        <geometry>
          <mesh>
            <scale>0.001 0.001 0.001</scale>
            <uri>model://iai_donbot_description/meshes/iai_wsg_50/GUIDE_WSG50_110.fbx</uri>
          </mesh>
        </geometry>
      </collision>
      <collision name="gripper_gripper_right_link_fixed_joint_lump__gripper_finger_right_link_collision_1">
        <pose frame="">0 0 0.023 0 -0 0</pose>
        <geometry>
          <mesh>
            <scale>0.001 0.001 0.001</scale>
            <uri>model://iai_donbot_description/meshes/iai_wsg_50/WSG-FMF.fbx</uri>
          </mesh>
        </geometry>
      </collision>
      <visual name="gripper_gripper_right_link_visual">
        <pose frame="">0 0 0 0 -0 0</pose>
        <geometry>
          <mesh>
            <scale>0.001 0.001 0.001</scale>
            <uri>model://iai_donbot_description/meshes/iai_wsg_50/GUIDE_WSG50_110.fbx</uri>
          </mesh>
        </geometry>
      </visual>
      <visual name="gripper_gripper_right_link_fixed_joint_lump__gripper_finger_right_link_visual_1">
        <pose frame="">0 0 0.023 0 -0 0</pose>
        <geometry>
          <mesh>
            <scale>0.001 0.001 0.001</scale>
            <uri>model://iai_donbot_description/meshes/iai_wsg_50/WSG-FMF.fbx</uri>
          </mesh>
        </geometry>
      </visual>
    </link>
    <joint name="gripper_base_gripper_right_joint" type="prismatic">
      <child>gripper_gripper_right_link</child>
      <parent>ur5_wrist_3_link</parent>
      <axis>
        <xyz>-0 0 1</xyz>
        <limit>
          <lower>0</lower>
          <upper>0.051</upper>
          <effort>10</effort>
          <velocity>0.42</velocity>
        </limit>
        <dynamics>
          <damping>1</damping>
          <friction>1</friction>
          <spring_reference>0</spring_reference>
          <spring_stiffness>0</spring_stiffness>
        </dynamics>
        <use_parent_model_frame>1</use_parent_model_frame>
      </axis>
    </joint>
  </model>
</sdf>
