<?xml version="1.0" encoding="utf-8"?>
<sdf version="1.6">
  <model name="ur5">
    <link name="base_link">
      <pose frame="">0 0 0 0 -0 0</pose>
      <inertial>
        <pose frame="">0 0 0 0 -0 0</pose>
        <mass>4</mass>
        <inertia>
          <ixx>0.00443333</ixx>
          <ixy>0</ixy>
          <ixz>0</ixz>
          <iyy>0.00443333</iyy>
          <iyz>0</iyz>
          <izz>0.0072</izz>
        </inertia>
      </inertial>
      <collision name="base_link_collision">
        <pose frame="">0 0 0 0 -0 0</pose>
        <geometry>
          <mesh>
            <scale>1 1 1</scale>
            <uri>model://ur_description/meshes/ur5/collision/base.stl</uri>
          </mesh>
        </geometry>
      </collision>
      <visual name="base_link_visual">
        <pose frame="">0 0 0 0 -0 0</pose>
        <geometry>
          <mesh>
            <scale>1 1 1</scale>
            <uri>model://ur_description/meshes/ur5/visual/base.dae</uri>
          </mesh>
        </geometry>
      </visual>
    </link>
    <link name="shoulder_link">
      <pose frame="">0 0 0.089159 0 -0 0</pose>
      <inertial>
        <pose frame="">0 0 0 0 -0 0</pose>
        <mass>3.7</mass>
        <inertia>
          <ixx>0.0102675</ixx>
          <ixy>0</ixy>
          <ixz>0</ixz>
          <iyy>0.0102675</iyy>
          <iyz>0</iyz>
          <izz>0.00666</izz>
        </inertia>
      </inertial>
      <collision name="shoulder_link_collision">
        <pose frame="">0 0 0 0 -0 0</pose>
        <geometry>
          <mesh>
            <scale>1 1 1</scale>
            <uri>model://ur_description/meshes/ur5/collision/shoulder.stl</uri>
          </mesh>
        </geometry>
      </collision>
      <visual name="shoulder_link_visual">
        <pose frame="">0 0 0 0 -0 0</pose>
        <geometry>
          <mesh>
            <scale>1 1 1</scale>
            <uri>model://ur_description/meshes/ur5/visual/shoulder.dae</uri>
          </mesh>
        </geometry>
      </visual>
    </link>
    <joint name="shoulder_pan_joint" type="revolute">
      <child>shoulder_link</child>
      <parent>base_link</parent>
      <axis>
        <xyz>0 0 1</xyz>
        <limit>
          <lower>-6.28319</lower>
          <upper>6.28319</upper>
          <effort>150</effort>
          <velocity>3.15</velocity>
        </limit>
        <dynamics>
          <damping>0</damping>
          <friction>0</friction>
          <spring_reference>0</spring_reference>
          <spring_stiffness>0</spring_stiffness>
        </dynamics>
        <use_parent_model_frame>1</use_parent_model_frame>
      </axis>
    </joint>
    <link name="upper_arm_link">
      <pose frame="">0 0.13585 0.089159 3.14159 1.57079 3.14159</pose>
      <inertial>
        <pose frame="">0 0 0.28 0 -0 0</pose>
        <mass>8.393</mass>
        <inertia>
          <ixx>0.226891</ixx>
          <ixy>0</ixy>
          <ixz>0</ixz>
          <iyy>0.226891</iyy>
          <iyz>0</iyz>
          <izz>0.0151074</izz>
        </inertia>
      </inertial>
      <collision name="upper_arm_link_collision">
        <pose frame="">0 0 0 0 -0 0</pose>
        <geometry>
          <mesh>
            <scale>1 1 1</scale>
            <uri>model://ur_description/meshes/ur5/collision/upperarm.stl</uri>
          </mesh>
        </geometry>
      </collision>
      <visual name="upper_arm_link_visual">
        <pose frame="">0 0 0 0 -0 0</pose>
        <geometry>
          <mesh>
            <scale>1 1 1</scale>
            <uri>model://ur_description/meshes/ur5/visual/upperarm.dae</uri>
          </mesh>
        </geometry>
      </visual>
    </link>
    <joint name="shoulder_lift_joint" type="revolute">
      <child>upper_arm_link</child>
      <parent>shoulder_link</parent>
      <axis>
        <xyz>0 1 0</xyz>
        <limit>
          <lower>-6.28319</lower>
          <upper>6.28319</upper>
          <effort>150</effort>
          <velocity>3.15</velocity>
        </limit>
        <dynamics>
          <damping>0</damping>
          <friction>0</friction>
          <spring_reference>0</spring_reference>
          <spring_stiffness>0</spring_stiffness>
        </dynamics>
        <use_parent_model_frame>1</use_parent_model_frame>
      </axis>
    </joint>
    <link name="forearm_link">
      <pose frame="">0.425 0.01615 0.089159 3.14159 1.57079 3.14159</pose>
      <inertial>
        <pose frame="">0 0 0.25 0 -0 0</pose>
        <mass>2.275</mass>
        <inertia>
          <ixx>0.0494433</ixx>
          <ixy>0</ixy>
          <ixz>0</ixz>
          <iyy>0.0494433</iyy>
          <iyz>0</iyz>
          <izz>0.004095</izz>
        </inertia>
      </inertial>
      <collision name="forearm_link_collision">
        <pose frame="">0 0 0 0 -0 0</pose>
        <geometry>
          <mesh>
            <scale>1 1 1</scale>
            <uri>model://ur_description/meshes/ur5/collision/forearm.stl</uri>
          </mesh>
        </geometry>
      </collision>
      <visual name="forearm_link_visual">
        <pose frame="">0 0 0 0 -0 0</pose>
        <geometry>
          <mesh>
            <scale>1 1 1</scale>
            <uri>model://ur_description/meshes/ur5/visual/forearm.dae</uri>
          </mesh>
        </geometry>
      </visual>
    </link>
    <joint name="elbow_joint" type="revolute">
      <child>forearm_link</child>
      <parent>upper_arm_link</parent>
      <axis>
        <xyz>0 1 0</xyz>
        <limit>
          <lower>-3.14159</lower>
          <upper>3.14159</upper>
          <effort>150</effort>
          <velocity>3.15</velocity>
        </limit>
        <dynamics>
          <damping>0</damping>
          <friction>0</friction>
          <spring_reference>0</spring_reference>
          <spring_stiffness>0</spring_stiffness>
        </dynamics>
        <use_parent_model_frame>1</use_parent_model_frame>
      </axis>
    </joint>
    <link name="wrist_1_link">
      <pose frame="">0.81725 0.01615 0.089159 3.14159 0 3.14159</pose>
      <inertial>
        <pose frame="">0 0 0 0 -0 0</pose>
        <mass>1.219</mass>
        <inertia>
          <ixx>0.111173</ixx>
          <ixy>0</ixy>
          <ixz>0</ixz>
          <iyy>0.111173</iyy>
          <iyz>0</iyz>
          <izz>0.21942</izz>
        </inertia>
      </inertial>
      <collision name="wrist_1_link_collision">
        <pose frame="">0 0 0 0 -0 0</pose>
        <geometry>
          <mesh>
            <scale>1 1 1</scale>
            <uri>model://ur_description/meshes/ur5/collision/wrist1.stl</uri>
          </mesh>
        </geometry>
      </collision>
      <visual name="wrist_1_link_visual">
        <pose frame="">0 0 0 0 -0 0</pose>
        <geometry>
          <mesh>
            <scale>1 1 1</scale>
            <uri>model://ur_description/meshes/ur5/visual/wrist1.dae</uri>
          </mesh>
        </geometry>
      </visual>
    </link>
    <joint name="wrist_1_joint" type="revolute">
      <child>wrist_1_link</child>
      <parent>forearm_link</parent>
      <axis>
        <xyz>0 1 0</xyz>
        <limit>
          <lower>-6.28319</lower>
          <upper>6.28319</upper>
          <effort>28</effort>
          <velocity>3.2</velocity>
        </limit>
        <dynamics>
          <damping>0</damping>
          <friction>0</friction>
          <spring_reference>0</spring_reference>
          <spring_stiffness>0</spring_stiffness>
        </dynamics>
        <use_parent_model_frame>1</use_parent_model_frame>
      </axis>
    </joint>
    <link name="wrist_2_link">
      <pose frame="">0.81725 0.10915 0.089159 3.14159 0 3.14159</pose>
      <inertial>
        <pose frame="">0 0 0 0 -0 0</pose>
        <mass>1.219</mass>
        <inertia>
          <ixx>0.111173</ixx>
          <ixy>0</ixy>
          <ixz>0</ixz>
          <iyy>0.111173</iyy>
          <iyz>0</iyz>
          <izz>0.21942</izz>
        </inertia>
      </inertial>
      <collision name="wrist_2_link_collision">
        <pose frame="">0 0 0 0 -0 0</pose>
        <geometry>
          <mesh>
            <scale>1 1 1</scale>
            <uri>model://ur_description/meshes/ur5/collision/wrist2.stl</uri>
          </mesh>
        </geometry>
      </collision>
      <visual name="wrist_2_link_visual">
        <pose frame="">0 0 0 0 -0 0</pose>
        <geometry>
          <mesh>
            <scale>1 1 1</scale>
            <uri>model://ur_description/meshes/ur5/visual/wrist2.dae</uri>
          </mesh>
        </geometry>
      </visual>
    </link>
    <joint name="wrist_2_joint" type="revolute">
      <child>wrist_2_link</child>
      <parent>wrist_1_link</parent>
      <axis>
        <xyz>0 0 -1</xyz>
        <limit>
          <lower>-6.28319</lower>
          <upper>6.28319</upper>
          <effort>28</effort>
          <velocity>3.2</velocity>
        </limit>
        <dynamics>
          <damping>0</damping>
          <friction>0</friction>
          <spring_reference>0</spring_reference>
          <spring_stiffness>0</spring_stiffness>
        </dynamics>
        <use_parent_model_frame>1</use_parent_model_frame>
      </axis>
    </joint>
    <link name="wrist_3_link">
      <pose frame="">0.81725 0.10915 -0.005491 3.14159 0 3.14159</pose>
      <inertial>
        <pose frame="">0 0 0 0 -0 0</pose>
        <mass>0.1879</mass>
        <inertia>
          <ixx>0.0171365</ixx>
          <ixy>0</ixy>
          <ixz>0</ixz>
          <iyy>0.0171365</iyy>
          <iyz>0</iyz>
          <izz>0.033822</izz>
        </inertia>
      </inertial>
      <collision name="wrist_3_link_collision">
        <pose frame="">0 0 0 0 -0 0</pose>
        <geometry>
          <mesh>
            <scale>1 1 1</scale>
            <uri>model://ur_description/meshes/ur5/collision/wrist3.stl</uri>
          </mesh>
        </geometry>
      </collision>
      <collision name="wrist_3_link_fixed_joint_lump__ee_link_collision_1">
        <pose frame="">-0 0.0723 0 0 -0 1.5708</pose>
        <geometry>
          <box>
            <size>0.01 0.01 0.01</size>
          </box>
        </geometry>
      </collision>
      <visual name="wrist_3_link_visual">
        <pose frame="">0 0 0 0 -0 0</pose>
        <geometry>
          <mesh>
            <scale>1 1 1</scale>
            <uri>model://ur_description/meshes/ur5/visual/wrist3.dae</uri>
          </mesh>
        </geometry>
      </visual>
    </link>
    <joint name="wrist_3_joint" type="revolute">
      <child>wrist_3_link</child>
      <parent>wrist_2_link</parent>
      <axis>
        <xyz>0 1 0</xyz>
        <limit>
          <lower>-6.28319</lower>
          <upper>6.28319</upper>
          <effort>28</effort>
          <velocity>3.2</velocity>
        </limit>
        <dynamics>
          <damping>0</damping>
          <friction>0</friction>
          <spring_reference>0</spring_reference>
          <spring_stiffness>0</spring_stiffness>
        </dynamics>
        <use_parent_model_frame>1</use_parent_model_frame>
      </axis>
    </joint>
    <static>0</static>
    <plugin name="ros_control" filename="libgazebo_ros_control.so"/>
  </model>
</sdf>
