<sdf version="1.6">
  <model name="kmr_iiwa">
    <link name="base_link">
      <pose frame="">0 0 0 0 -0 0</pose>
      <inertial>
        <pose frame="">0.371273 -0 0.96566 0 -0 0</pose>
        <mass>5</mass>
        <inertia>
          <ixx>0.04</ixx>
          <ixy>6.33077e-14</ixy>
          <ixz>-0.01</ixz>
          <iyy>0.06</iyy>
          <iyz>8.359e-14</iyz>
          <izz>0.04</izz>
        </inertia>
      </inertial>
      <collision name="base_link_collision">
        <pose frame="">0 0 0 0 -0 0</pose>
        <geometry>
          <mesh>
            <scale>1 1 1</scale>
            <uri>model://meshes/fbx/kmp200_export/kmp200_export.fbx</uri>
          </mesh>
        </geometry>
      </collision>
      <collision name="base_link_fixed_joint_lump__iiwa_link_0_collision_1">
        <pose frame="">0.392486 -0 0.845452 0 0.785398 0</pose>
        <geometry>
          <mesh>
            <scale>1 1 1</scale>
            <uri>model://meshes/fbx/iiwa14/collision/link_0.fbx</uri>
          </mesh>
        </geometry>
        <surface>
          <contact>
            <ode/>
          </contact>
          <friction>
            <ode>
              <mu>0.2</mu>
              <mu2>0.2</mu2>
            </ode>
          </friction>
        </surface>
      </collision>
      <visual name="base_link_visual">
        <pose frame="">0 0 0 0 -0 0</pose>
        <geometry>
          <mesh>
            <scale>1 1 1</scale>
            <uri>model://meshes/fbx/kmp200_export/kmp200_3ds_export.fbx</uri>
          </mesh>
        </geometry>
      </visual>
      <visual name="base_link_fixed_joint_lump__angle_adapter_base_visual_1">
        <pose frame="">0.363 0 0.7 0 -0 1.5708</pose>
        <geometry>
          <mesh>
            <scale>1 1 1</scale>
            <uri>model://meshes/fbx/angle_adapter/angle_adapter_base.fbx</uri>
          </mesh>
        </geometry>
      </visual>
      <visual name="base_link_fixed_joint_lump__angle_adapter_plate_visual_2">
        <pose frame="">0.392486 -0 0.845452 0.785398 0 1.5708</pose>
        <geometry>
          <mesh>
            <scale>1 1 1</scale>
            <uri>model://meshes/fbx/angle_adapter/angle_adapter_plate.fbx</uri>
          </mesh>
        </geometry>
      </visual>
      <visual name="base_link_fixed_joint_lump__iiwa_link_0_visual_3">
        <pose frame="">0.392486 -0 0.845452 0 0.785398 0</pose>
        <geometry>
          <mesh>
            <scale>1 1 1</scale>
            <uri>model://meshes/fbx/iiwa14/visual/link_0.fbx</uri>
          </mesh>
        </geometry>
        <material>
          <script>
            <name>Gazebo/Grey</name>
            <uri>file://media/materials/scripts/gazebo.material</uri>
          </script>
        </material>
      </visual>
      <gravity>1</gravity>
      <velocity_decay/>
    </link>
    <link name="iiwa_link_1">
      <pose frame="">0.503856 -0 0.956821 0 0.785398 0</pose>
      <inertial>
        <pose frame="">0 -0.03 0.12 0 -0 0</pose>
        <mass>4</mass>
        <inertia>
          <ixx>0.1</ixx>
          <ixy>0</ixy>
          <ixz>0</ixz>
          <iyy>0.09</iyy>
          <iyz>0</iyz>
          <izz>0.02</izz>
        </inertia>
      </inertial>
      <collision name="iiwa_link_1_collision">
        <pose frame="">0 0 0 0 -0 0</pose>
        <geometry>
          <mesh>
            <scale>1 1 1</scale>
            <uri>model://meshes/fbx/iiwa14/collision/link_1.fbx</uri>
          </mesh>
        </geometry>
        <surface>
          <contact>
            <ode/>
          </contact>
          <friction>
            <ode>
              <mu>0.2</mu>
              <mu2>0.2</mu2>
            </ode>
          </friction>
        </surface>
      </collision>
      <visual name="iiwa_link_1_visual">
        <pose frame="">0 0 0 0 -0 0</pose>
        <geometry>
          <mesh>
            <scale>1 1 1</scale>
            <uri>model://meshes/fbx/iiwa14/visual/link_1.fbx</uri>
          </mesh>
        </geometry>
        <material>
          <script>
            <name>Gazebo/Orange</name>
            <uri>file://media/materials/scripts/gazebo.material</uri>
          </script>
        </material>
      </visual>
      <gravity>1</gravity>
      <velocity_decay/>
    </link>
    <joint name="iiwa_joint_1" type="revolute">
      <child>iiwa_link_1</child>
      <parent>base_link</parent>
      <axis>
        <xyz>0.707107 -0 0.707107</xyz>
        <limit>
          <lower>-2.96706</lower>
          <upper>2.96706</upper>
          <effort>300</effort>
          <velocity>10</velocity>
        </limit>
        <dynamics>
          <damping>0.5</damping>
          <friction>0</friction>
          <spring_reference>0</spring_reference>
          <spring_stiffness>0</spring_stiffness>
        </dynamics>
        <use_parent_model_frame>1</use_parent_model_frame>
      </axis>
    </joint>
    <link name="iiwa_link_2">
      <pose frame="">0.647045 -0 1.10001 1.5708 -0.785398 -3.14159</pose>
      <inertial>
        <pose frame="">0.0003 0.059 0.042 0 -0 0</pose>
        <mass>4</mass>
        <inertia>
          <ixx>0.05</ixx>
          <ixy>0</ixy>
          <ixz>0</ixz>
          <iyy>0.018</iyy>
          <iyz>0</iyz>
          <izz>0.044</izz>
        </inertia>
      </inertial>
      <collision name="iiwa_link_2_collision">
        <pose frame="">0 0 0 0 -0 0</pose>
        <geometry>
          <mesh>
            <scale>1 1 1</scale>
            <uri>model://meshes/fbx/iiwa14/collision/link_2.fbx</uri>
          </mesh>
        </geometry>
        <surface>
          <contact>
            <ode/>
          </contact>
          <friction>
            <ode>
              <mu>0.2</mu>
              <mu2>0.2</mu2>
            </ode>
          </friction>
        </surface>
      </collision>
      <visual name="iiwa_link_2_visual">
        <pose frame="">0 0 0 0 -0 0</pose>
        <geometry>
          <mesh>
            <scale>1 1 1</scale>
            <uri>model://meshes/fbx/iiwa14/visual/link_2.fbx</uri>
          </mesh>
        </geometry>
        <material>
          <script>
            <name>Gazebo/Orange</name>
            <uri>file://media/materials/scripts/gazebo.material</uri>
          </script>
        </material>
      </visual>
      <gravity>1</gravity>
      <velocity_decay/>
    </link>
    <joint name="iiwa_joint_2" type="revolute">
      <child>iiwa_link_2</child>
      <parent>iiwa_link_1</parent>
      <axis>
        <xyz>0 1 0</xyz>
        <limit>
          <lower>-2.0944</lower>
          <upper>2.0944</upper>
          <effort>300</effort>
          <velocity>10</velocity>
        </limit>
        <dynamics>
          <damping>0.5</damping>
          <friction>0</friction>
          <spring_reference>0</spring_reference>
          <spring_stiffness>0</spring_stiffness>
        </dynamics>
        <use_parent_model_frame>1</use_parent_model_frame>
      </axis>
    </joint>
    <link name="iiwa_link_3">
      <pose frame="">0.791648 -0 1.24461 0 0.785398 0</pose>
      <inertial>
        <pose frame="">0 0.03 0.13 0 -0 0</pose>
        <mass>3</mass>
        <inertia>
          <ixx>0.08</ixx>
          <ixy>0</ixy>
          <ixz>0</ixz>
          <iyy>0.075</iyy>
          <iyz>0</iyz>
          <izz>0.01</izz>
        </inertia>
      </inertial>
      <collision name="iiwa_link_3_collision">
        <pose frame="">0 0 0 0 -0 0</pose>
        <geometry>
          <mesh>
            <scale>1 1 1</scale>
            <uri>model://meshes/fbx/iiwa14/collision/link_3.fbx</uri>
          </mesh>
        </geometry>
        <surface>
          <contact>
            <ode/>
          </contact>
          <friction>
            <ode>
              <mu>0.2</mu>
              <mu2>0.2</mu2>
            </ode>
          </friction>
        </surface>
      </collision>
      <visual name="iiwa_link_3_visual">
        <pose frame="">0 0 0 0 -0 0</pose>
        <geometry>
          <mesh>
            <scale>1 1 1</scale>
            <uri>model://meshes/fbx/iiwa14/visual/link_3.fbx</uri>
          </mesh>
        </geometry>
        <material>
          <script>
            <name>Gazebo/Orange</name>
            <uri>file://media/materials/scripts/gazebo.material</uri>
          </script>
        </material>
      </visual>
      <gravity>1</gravity>
      <velocity_decay/>
    </link>
    <joint name="iiwa_joint_3" type="revolute">
      <child>iiwa_link_3</child>
      <parent>iiwa_link_2</parent>
      <axis>
        <xyz>0.707107 -0 0.707107</xyz>
        <limit>
          <lower>-2.96706</lower>
          <upper>2.96706</upper>
          <effort>300</effort>
          <velocity>10</velocity>
        </limit>
        <dynamics>
          <damping>0.5</damping>
          <friction>0</friction>
          <spring_reference>0</spring_reference>
          <spring_stiffness>0</spring_stiffness>
        </dynamics>
        <use_parent_model_frame>1</use_parent_model_frame>
      </axis>
    </joint>
    <link name="iiwa_link_4">
      <pose frame="">0.94403 -0 1.397 1.5708 0.785398 0</pose>
      <inertial>
        <pose frame="">0 0.067 0.034 0 -0 0</pose>
        <mass>2.7</mass>
        <inertia>
          <ixx>0.03</ixx>
          <ixy>0</ixy>
          <ixz>0</ixz>
          <iyy>0.01</iyy>
          <iyz>0</iyz>
          <izz>0.029</izz>
        </inertia>
      </inertial>
      <collision name="iiwa_link_4_collision">
        <pose frame="">0 0 0 0 -0 0</pose>
        <geometry>
          <mesh>
            <scale>1 1 1</scale>
            <uri>model://meshes/fbx/iiwa14/collision/link_4.fbx</uri>
          </mesh>
        </geometry>
        <surface>
          <contact>
            <ode/>
          </contact>
          <friction>
            <ode>
              <mu>0.2</mu>
              <mu2>0.2</mu2>
            </ode>
          </friction>
        </surface>
      </collision>
      <visual name="iiwa_link_4_visual">
        <pose frame="">0 0 0 0 -0 0</pose>
        <geometry>
          <mesh>
            <scale>1 1 1</scale>
            <uri>model://meshes/fbx/iiwa14/visual/link_4.fbx</uri>
          </mesh>
        </geometry>
        <material>
          <script>
            <name>Gazebo/Orange</name>
            <uri>file://media/materials/scripts/gazebo.material</uri>
          </script>
        </material>
      </visual>
      <gravity>1</gravity>
      <velocity_decay/>
    </link>
    <joint name="iiwa_joint_4" type="revolute">
      <child>iiwa_link_4</child>
      <parent>iiwa_link_3</parent>
      <axis>
        <xyz>0 -1 -0</xyz>
        <limit>
          <lower>-2.0944</lower>
          <upper>2.0944</upper>
          <effort>300</effort>
          <velocity>10</velocity>
        </limit>
        <dynamics>
          <damping>0.5</damping>
          <friction>0</friction>
          <spring_reference>0</spring_reference>
          <spring_stiffness>0</spring_stiffness>
        </dynamics>
        <use_parent_model_frame>1</use_parent_model_frame>
      </axis>
    </joint>
    <link name="iiwa_link_5">
      <pose frame="">1.07449 -0 1.52746 0 -0.785398 -3.14159</pose>
      <inertial>
        <pose frame="">0.0001 0.021 0.076 0 -0 0</pose>
        <mass>1.7</mass>
        <inertia>
          <ixx>0.02</ixx>
          <ixy>0</ixy>
          <ixz>0</ixz>
          <iyy>0.018</iyy>
          <iyz>0</iyz>
          <izz>0.005</izz>
        </inertia>
      </inertial>
      <collision name="iiwa_link_5_collision">
        <pose frame="">0 0 0 0 -0 0</pose>
        <geometry>
          <mesh>
            <scale>1 1 1</scale>
            <uri>model://meshes/fbx/iiwa14/collision/link_5.fbx</uri>
          </mesh>
        </geometry>
        <surface>
          <contact>
            <ode/>
          </contact>
          <friction>
            <ode>
              <mu>0.2</mu>
              <mu2>0.2</mu2>
            </ode>
          </friction>
        </surface>
      </collision>
      <visual name="iiwa_link_5_visual">
        <pose frame="">0 0 0 0 -0 0</pose>
        <geometry>
          <mesh>
            <scale>1 1 1</scale>
            <uri>model://meshes/fbx/iiwa14/visual/link_5.fbx</uri>
          </mesh>
        </geometry>
        <material>
          <script>
            <name>Gazebo/Orange</name>
            <uri>file://media/materials/scripts/gazebo.material</uri>
          </script>
        </material>
      </visual>
      <gravity>1</gravity>
      <velocity_decay/>
    </link>
    <joint name="iiwa_joint_5" type="revolute">
      <child>iiwa_link_5</child>
      <parent>iiwa_link_4</parent>
      <axis>
        <xyz>0.707107 0 0.707107</xyz>
        <limit>
          <lower>-2.96706</lower>
          <upper>2.96706</upper>
          <effort>300</effort>
          <velocity>10</velocity>
        </limit>
        <dynamics>
          <damping>0.5</damping>
          <friction>0</friction>
          <spring_reference>0</spring_reference>
          <spring_stiffness>0</spring_stiffness>
        </dynamics>
        <use_parent_model_frame>1</use_parent_model_frame>
      </axis>
    </joint>
    <link name="iiwa_link_6">
      <pose frame="">1.22687 -0 1.67984 1.5708 -0.785398 -3.14159</pose>
      <inertial>
        <pose frame="">0 0.0006 0.0004 0 -0 0</pose>
        <mass>1.8</mass>
        <inertia>
          <ixx>0.005</ixx>
          <ixy>0</ixy>
          <ixz>0</ixz>
          <iyy>0.0036</iyy>
          <iyz>0</iyz>
          <izz>0.0047</izz>
        </inertia>
      </inertial>
      <collision name="iiwa_link_6_collision">
        <pose frame="">0 0 0 0 -0 0</pose>
        <geometry>
          <mesh>
            <scale>1 1 1</scale>
            <uri>model://meshes/fbx/iiwa14/collision/link_6.fbx</uri>
          </mesh>
        </geometry>
        <surface>
          <contact>
            <ode/>
          </contact>
          <friction>
            <ode>
              <mu>0.2</mu>
              <mu2>0.2</mu2>
            </ode>
          </friction>
        </surface>
      </collision>
      <visual name="iiwa_link_6_visual">
        <pose frame="">0 0 0 0 -0 0</pose>
        <geometry>
          <mesh>
            <scale>1 1 1</scale>
            <uri>model://meshes/fbx/iiwa14/visual/link_6.fbx</uri>
          </mesh>
        </geometry>
        <material>
          <script>
            <name>Gazebo/Orange</name>
            <uri>file://media/materials/scripts/gazebo.material</uri>
          </script>
        </material>
      </visual>
      <gravity>1</gravity>
      <velocity_decay/>
    </link>
    <joint name="iiwa_joint_6" type="revolute">
      <child>iiwa_link_6</child>
      <parent>iiwa_link_5</parent>
      <axis>
        <xyz>-0 1 0</xyz>
        <limit>
          <lower>-2.0944</lower>
          <upper>2.0944</upper>
          <effort>300</effort>
          <velocity>10</velocity>
        </limit>
        <dynamics>
          <damping>0.5</damping>
          <friction>0</friction>
          <spring_reference>0</spring_reference>
          <spring_stiffness>0</spring_stiffness>
        </dynamics>
        <use_parent_model_frame>1</use_parent_model_frame>
      </axis>
    </joint>
    <link name="iiwa_link_7">
      <pose frame="">1.28415 -0 1.73711 0 0.785398 0</pose>
      <inertial>
        <pose frame="">0 0 0.049591 0 -0 0</pose>
        <mass>0.55</mass>
        <inertia>
          <ixx>1.00158</ixx>
          <ixy>0</ixy>
          <ixz>0</ixz>
          <iyy>1.00158</iyy>
          <iyz>0</iyz>
          <izz>1.001</izz>
        </inertia>
      </inertial>
      <collision name="iiwa_link_7_collision">
        <pose frame="">0 0 0 0 -0 0</pose>
        <geometry>
          <mesh>
            <scale>1 1 1</scale>
            <uri>model://meshes/fbx/iiwa14/collision/link_7.fbx</uri>
          </mesh>
        </geometry>
        <surface>
          <contact>
            <ode/>
          </contact>
          <friction>
            <ode>
              <mu>0.2</mu>
              <mu2>0.2</mu2>
            </ode>
          </friction>
        </surface>
      </collision>
      <collision name="iiwa_link_7_fixed_joint_lump__gripper_base_link_collision_1">
        <pose frame="">0 0 0.0851 0 -0 -3.14159</pose>
        <geometry>
          <mesh>
            <scale>1 1 1</scale>
            <uri>model://meshes/fbx/wsg_50/WSG50_110.fbx</uri>
          </mesh>
        </geometry>
        <surface>
          <contact>
            <ode/>
          </contact>
          <friction>
            <ode/>
          </friction>
        </surface>
      </collision>
      <collision name="iiwa_link_7_fixed_joint_lump__camera_holder_link_collision_2">
        <pose frame="">0 0 0.0851 0 -0 0</pose>
        <geometry>
          <mesh>
            <scale>1 1 1</scale>
            <uri>model://meshes/refills_camera_holder_and_camera.fbx</uri>
          </mesh>
        </geometry>
      </collision>
      <collision name="iiwa_link_7_fixed_joint_lump__wrist_collision_collision_3">
        <pose frame="">0 0 0.04 0 -0 0</pose>
        <geometry>
          <cylinder>
            <length>0.08</length>
            <radius>0.04</radius>
          </cylinder>
        </geometry>
      </collision>
      <visual name="iiwa_link_7_visual">
        <pose frame="">0 0 0 0 -0 0</pose>
        <geometry>
          <mesh>
            <scale>1 1 1</scale>
            <uri>model://meshes/fbx/iiwa14/visual/link_7.fbx</uri>
          </mesh>
        </geometry>
        <material>
          <script>
            <name>Gazebo/Grey</name>
            <uri>file://media/materials/scripts/gazebo.material</uri>
          </script>
        </material>
      </visual>
      <visual name="iiwa_link_7_fixed_joint_lump__fwk_fwa_050_frame_in_visual_1">
        <pose frame="">0 0 0.071 0 -0 0</pose>
        <geometry>
          <mesh>
            <scale>0.001 0.001 0.001</scale>
            <uri>model://meshes/fbx/iai_adapters/fwk_fwa_050_simple.fbx</uri>
          </mesh>
        </geometry>
      </visual>
      <visual name="iiwa_link_7_fixed_joint_lump__gripper_base_link_visual_2">
        <pose frame="">0 0 0.0851 0 -0 -3.14159</pose>
        <geometry>
          <mesh>
            <scale>1 1 1</scale>
            <uri>model://meshes/fbx/wsg_50/WSG50_110.fbx</uri>
          </mesh>
        </geometry>
        <material>
          <script>
            <name>Gazebo/Grey</name>
            <uri>file://media/materials/scripts/gazebo.material</uri>
          </script>
        </material>
      </visual>
      <visual name="iiwa_link_7_fixed_joint_lump__camera_holder_link_visual_3">
        <pose frame="">0 0 0.0851 0 -0 0</pose>
        <geometry>
          <mesh>
            <scale>1 1 1</scale>
            <uri>model://meshes/refills_camera_holder_and_camera.fbx</uri>
          </mesh>
        </geometry>
      </visual>
      <visual name="iiwa_link_7_fixed_joint_lump__camera_link_visual_4">
        <pose frame="">-0.001329 0.06619 0.116683 0.231224 -0.003491 0.006955</pose>
        <geometry>
          <cylinder>
            <length>0.005</length>
            <radius>0.001</radius>
          </cylinder>
        </geometry>
      </visual>
      <velocity_decay/>
      <gravity>1</gravity>
      <velocity_decay/>
    </link>
    <joint name="iiwa_joint_7" type="revolute">
      <child>iiwa_link_7</child>
      <parent>iiwa_link_6</parent>
      <axis>
        <xyz>0.707107 -0 0.707107</xyz>
        <limit>
          <lower>-3.05433</lower>
          <upper>3.05433</upper>
          <effort>300</effort>
          <velocity>10</velocity>
        </limit>
        <dynamics>
          <damping>0.5</damping>
          <friction>0</friction>
          <spring_reference>0</spring_reference>
          <spring_stiffness>0</spring_stiffness>
        </dynamics>
        <use_parent_model_frame>1</use_parent_model_frame>
      </axis>
      <physics>
        <provide_feedback>1</provide_feedback>
        <ode>
          <provide_feedback>1</provide_feedback>
          <limit>
            <cfm>0</cfm>
            <erp>0.2</erp>
          </limit>
        </ode>
      </physics>
    </joint>
    <link name="gripper_gripper_left_link">
      <pose frame="">1.34432 -0 1.79729 -0 -0.785398 -3.14159</pose>
      <inertial>
        <pose frame="">0 0 0.0115 0 -0 0</pose>
        <mass>0.2</mass>
        <inertia>
          <ixx>2.00003</ixx>
          <ixy>0</ixy>
          <ixz>0</ixz>
          <iyy>2.00003</iyy>
          <iyz>0</iyz>
          <izz>2</izz>
        </inertia>
      </inertial>
      <collision name="gripper_gripper_left_link_collision">
        <pose frame="">0 0 0 0 -0 0</pose>
        <geometry>
          <mesh>
            <scale>0.001 0.001 0.001</scale>
            <uri>model://meshes/fbx/wsg_50/GUIDE_WSG50_110.fbx</uri>
          </mesh>
        </geometry>
        <surface>
          <contact>
            <ode/>
          </contact>
          <friction>
            <ode/>
          </friction>
        </surface>
      </collision>
      <collision name="gripper_gripper_left_link_fixed_joint_lump__gripper_finger_left_link_collision_1">
        <pose frame="">0 0 0.023 0 -0 0</pose>
        <geometry>
          <mesh>
            <scale>0.001 0.001 0.001</scale>
            <uri>model://meshes/fbx/wsg_50/WSG-FMF.fbx</uri>
          </mesh>
        </geometry>
      </collision>
      <visual name="gripper_gripper_left_link_visual">
        <pose frame="">0 0 0 0 -0 0</pose>
        <geometry>
          <mesh>
            <scale>0.001 0.001 0.001</scale>
            <uri>model://meshes/fbx/wsg_50/GUIDE_WSG50_110.fbx</uri>
          </mesh>
        </geometry>
        <material>
          <script>
            <name>Gazebo/Blue</name>
            <uri>file://media/materials/scripts/gazebo.material</uri>
          </script>
        </material>
      </visual>
      <visual name="gripper_gripper_left_link_fixed_joint_lump__gripper_finger_left_link_visual_1">
        <pose frame="">0 0 0.023 0 -0 0</pose>
        <geometry>
          <mesh>
            <scale>0.001 0.001 0.001</scale>
            <uri>model://meshes/fbx/wsg_50/WSG-FMF.fbx</uri>
          </mesh>
        </geometry>
      </visual>
      <gravity>1</gravity>
      <velocity_decay/>
    </link>
    <joint name="gripper_base_gripper_left_joint" type="prismatic">
      <child>gripper_gripper_left_link</child>
      <parent>iiwa_link_7</parent>
      <axis>
        <xyz>-0.707107 -0 0.707107</xyz>
        <limit>
          <lower>-0.055</lower>
          <upper>-0.0027</upper>
          <effort>1</effort>
          <velocity>0.42</velocity>
        </limit>
        <dynamics>
          <damping>100</damping>
          <friction>100</friction>
          <spring_reference>0</spring_reference>
          <spring_stiffness>0</spring_stiffness>
        </dynamics>
        <use_parent_model_frame>1</use_parent_model_frame>
      </axis>
    </joint>
    <link name="gripper_gripper_right_link">
      <pose frame="">1.34432 -0 1.79729 -3e-06 0.785398 -4e-06</pose>
      <inertial>
        <pose frame="">0 0 0.0115 0 -0 0</pose>
        <mass>0.2</mass>
        <inertia>
          <ixx>2.00003</ixx>
          <ixy>0</ixy>
          <ixz>0</ixz>
          <iyy>2.00003</iyy>
          <iyz>0</iyz>
          <izz>2</izz>
        </inertia>
      </inertial>
      <collision name="gripper_gripper_right_link_collision">
        <pose frame="">0 0 0 0 -0 0</pose>
        <geometry>
          <mesh>
            <scale>0.001 0.001 0.001</scale>
            <uri>model://meshes/fbx/wsg_50/GUIDE_WSG50_110.fbx</uri>
          </mesh>
        </geometry>
      </collision>
      <collision name="gripper_gripper_right_link_fixed_joint_lump__gripper_finger_right_link_collision_1">
        <pose frame="">0 0 0.023 0 -0 0</pose>
        <geometry>
          <mesh>
            <scale>0.001 0.001 0.001</scale>
            <uri>model://meshes/fbx/wsg_50/WSG-FMF.fbx</uri>
          </mesh>
        </geometry>
      </collision>
      <visual name="gripper_gripper_right_link_visual">
        <pose frame="">0 0 0 0 -0 0</pose>
        <geometry>
          <mesh>
            <scale>0.001 0.001 0.001</scale>
            <uri>model://meshes/fbx/wsg_50/GUIDE_WSG50_110.fbx</uri>
          </mesh>
        </geometry>
      </visual>
      <visual name="gripper_gripper_right_link_fixed_joint_lump__gripper_finger_right_link_visual_1">
        <pose frame="">0 0 0.023 0 -0 0</pose>
        <geometry>
          <mesh>
            <scale>0.001 0.001 0.001</scale>
            <uri>model://meshes/fbx/wsg_50/WSG-FMF.fbx</uri>
          </mesh>
        </geometry>
      </visual>
    </link>
    <joint name="gripper_joint" type="prismatic">
      <child>gripper_gripper_right_link</child>
      <parent>gripper_gripper_left_link</parent>
      <axis>
        <xyz>-0.707107 3e-06 0.707107</xyz>
        <limit>
          <lower>0.0065</lower>
          <upper>0.109</upper>
          <effort>1</effort>
          <velocity>0.42</velocity>
        </limit>
        <dynamics>
          <damping>100</damping>
          <friction>100</friction>
          <spring_reference>0</spring_reference>
          <spring_stiffness>0</spring_stiffness>
        </dynamics>
        <use_parent_model_frame>1</use_parent_model_frame>
      </axis>
    </joint>
    <plugin name="ft_sensor" filename="libgazebo_ros_ft_sensor.so">
      <updateRate>50.0</updateRate>
      <topicName>/iiwa/state/CartesianWrench</topicName>
      <jointName>iiwa_joint_7</jointName>
    </plugin>
    <static>0</static>
    <plugin name="gazebo_ros_control" filename="libgazebo_ros_control.so">
      <robotNamespace>/iiwa</robotNamespace>
    </plugin>
  </model>
</sdf>
